Workbook

Sheet Introduction
A1: Welcome to PollBase, my database of voting intention opinion polls since 1943, the largest such public dataset. The leader and government ratings go back to 1938 but has more gaps in them than the voting intention records.
A3: It is updated each quarter, adding in both a further three months of data and also usually including other data additions or corrections for earlier decades.
A5: Many people have helped over the years with this data answering all sorts of questions from me. Particular thanks for providing an exceptionally large number of answers go to Will Jennings, Roger Mortimore, Anthony Wells and the staff of Swiss Cottage public library.
A7: You are very welcome to use this data. I only ask two things in return - that if you spot any errors or omissions you let me know and that you credit the source of the data (including, if you make use of it online, a link back to https://www.markpack.org.uk/opinion-polls/). Thank you.
A9: Mark Pack
A10: Mark.Pack@LibDemNewswire.com / www.TheWeekinPolls.co.uk
A12: Geography
A13: Note: unless otherwise noted, the polls listed here were conducted across Great Britain rather than the UK (ie excluding Northern Ireland). The general election vote shares are therefore also given on a GB rather than UK basis.
A15: Survation is the pollster that has most varied between GB and UK polls and so its polls are noted as being GB or UK as applicable.
A16: Opinium voting intentions are for GB, but from around 2018 its other questions (leader ratings, etc.) are UK.
A18: Seat projections
A19: These are included for MRP (and similar) models where they are based on specific polling for that model. MRPs based on polls of polls and similar reuse of other polling are not included.
A21: The seat projection numbers (included for the 2015-17 Parliament and more recent ones) are at the right hand side; you may have to scroll some way to get to them.

Sheet Abbreviations
A1: Abbreviations used for publishers of polls | D1: Abbreviations etc. used for pollsters
A3: BBC | B3: BBC | D3: Gallup | E3: Also known in its early days as BIPO/British Institute of Public Opinion
A4: BEM | B4: Birmingham Evening Mail | D4: GGF | E4: Good Growth Foundation Insights
A5: Ben Ansell | B5: Professor Ben Ansell (newsletter) | D5: R+W | E5: Redfield & Wilton Stratergies
A6: BfB | B6: Best for Britain (pressure group/think tank)
A7: Bloom | B7: Bloomberg
A8: Br Elect | B8: Britain Elects (polling website)
A9: Brexit Exp | B9: Brexit Express (pressure group)
A10: BT | B10: Byline Times
A11: C4 | B11: Channel 4
A12: CCC | B12: ?
A13: Capibus | B13: Capibus
A14: Capital | B14: Capital Radio
A15: Compass | B15: Compass (left wing pressure group)
A16: Con | B16: Conservative Party
A17: Const Com | B17: Constitutional Commission
... A126: Yorks TV | B126: Yorkshire TV
A127: 18 | B127: ?
A128: 38 Degrees | B128: 38 Degrees (pressure group/think tank)

Sheet 38-45
A1: Year | B1: Month | C1: Fieldwork | E1: Published | F1: Polling | G1: Publisher | H1: Con | J1: Lab | L1: LD | N1: Con lead | Q1: Leader: | R1: Con good | S1: Con bad | T1: Con net | U1: Lab good | V1: Lab bad | W1: Lab net | X1: LD good | Y1: LD bad | Z1: LD net | AA1: Question
A2: 1938 | B2: Oct | F2: Gallup | R2: =0.57*90 -> 51.3 | S2: =0.43*90 -> 38.7 | T2: =R2-S2 -> 12.6 | AA2: Are you satistified with X as Y?
B3: Nov | F3: Gallup | R3: =0.55*89 -> 48.95 | S3: =0.45*89 -> 40.05 | T3: =R3-S3 -> 8.9 | AA3: Are you satistified with X as Y?
B4: Dec | F4: Gallup | R4: =0.56*91 -> 50.96 | S4: =0.44*91 -> 40.04 | T4: =R4-S4 -> 10.92 | AA4: Are you satistified with X as Y?
A5: 1939 | B5: Jan | F5: Gallup | R5: =0.57*94 -> 53.58 | S5: =0.43*94 -> 40.42 | T5: =R5-S5 -> 13.16 | AA5: Are you satistified with X as Y?
B6: Feb | F6: Gallup | H6: 53.2 | J6: 46.8 | N6: =H6-J6 -> 6.4 | R6: =0.57*85 -> 48.45 | S6: =0.43*85 -> 36.55 | T6: =R6-S6 -> 11.9 | AA6: Are you satistified with X as Y?
B7: Mar | F7: Gallup | R7: =58*0.9 -> 52.2 | S7: =42*0.9 -> 37.8 | T7: =R7-S7 -> 14.4 | AA7: Are you satistified with X as Y?
B8: Apr | F8: Gallup | R8: =0.59*93 -> 54.87 | S8: =0.41*93 -> 38.13 | T8: =R8-S8 -> 16.74 | AA8: Are you satistified with X as Y?
B9: May | F9: Gallup | R9: =0.55*96 -> 52.8 | S9: =0.45*96 -> 43.2 | T9: =R9-S9 -> 9.6 | AA9: Are you satistified with X as Y?
B10: Jun | F10: Gallup | R10: =0.55*95 -> 52.25 | S10: =0.45*95 -> 42.75 | T10: =R10-S10 -> 9.5 | AA10: Are you satistified with X as Y?
B11: Jul | F11: Gallup | R11: =0.59*93 -> 54.87 | S11: =0.41*93 -> 38.13 | T11: =R11-S11 -> 16.74 | AA11: Are you satistified with X as Y?
B12: Oct | F12: Gallup | R12: 65 | S12: 29 | T12: =R12-S12 -> 36 | AA12: Are you satistified with X as Y?
B13: Nov | F13: Gallup | R13: 68 | S13: 27 | T13: =R13-S13 -> 41 | AA13: Are you satistified with X as Y?
B14: Dec | F14: Gallup | H14: 64.3 | J14: 35.7 | N14: =H14-J14 -> 28.6 | R14: 64 | S14: 30 | T14: =R14-S14 -> 34 | AA14: In general, do you approve or disapprove of X as Y?
A15: 1940 | B15: Jan | F15: Gallup | R15: 56 | S15: 32 | T15: =R15-S15 -> 24 | AA15: In general, do you approve or disapprove of X as Y?
B16: Feb | F16: Gallup | H16: 65.4 | J16: 34.6 | N16: =H16-J16 -> 30.8 | R16: 59 | S16: 30 | T16: =R16-S16 -> 29 | AA16: In general, do you approve or disapprove of X as Y?
B17: Mar | F17: Gallup | R17: 57 | S17: 36 | T17: =R17-S17 -> 21 | AA17: In general, do you approve or disapprove of X as Y?
B18: May | F18: Gallup | R18: 33 | S18: 60 | T18: =R18-S18 -> -27 | AA18: In general, do you approve or disapprove of X as Y?
B19: Jul | F19: Gallup | R19: 88 | S19: 7 | T19: =R19-S19 -> 81 | AA19: In general, do you approve or disapprove of X as Y?
B20: Oct | F20: Gallup | R20: 89 | S20: 6 | T20: =R20-S20 -> 83 | AA20: In general, do you approve or disapprove of X as Y?
B21: Nov | F21: Gallup | R21: 88 | S21: 7 | T21: =R21-S21 -> 81 | AA21: In general, do you approve or disapprove of X as Y?
A22: 1941 | B22: Jan | F22: Gallup | R22: 85 | S22: 7 | T22: =R22-S22 -> 78 | AA22: In general, do you approve or disapprove of X as Y?
B23: Mar | F23: Gallup | R23: 88 | S23: 7 | T23: =R23-S23 -> 81 | AA23: In general, do you approve or disapprove of X as Y?
B24: Jun | F24: Gallup | R24: 87 | S24: 9 | T24: =R24-S24 -> 78 | AA24: In general, do you approve or disapprove of X as Y?
B25: Oct | F25: Gallup | R25: 84 | S25: 11 | T25: =R25-S25 -> 73 | AA25: In general, do you approve or disapprove of X as Y?
B26: Dec | F26: Gallup | R26: 88 | S26: 8 | T26: =R26-S26 -> 80 | AA26: In general, do you approve or disapprove of X as Y?
A27: 1942 | B27: Jan | F27: Gallup | R27: 89 | S27: 7 | T27: =R27-S27 -> 82 | AA27: In general, do you approve or disapprove of X as Y?
B28: Feb | F28: Gallup | R28: 82 | S28: 11 | T28: =R28-S28 -> 71 | AA28: In general, do you approve or disapprove of X as Y?
B29: Mar | F29: Gallup | R29: 81 | S29: 13 | T29: =R29-S29 -> 68 | AA29: In general, do you approve or disapprove of X as Y?
B30: Apr | F30: Gallup | R30: 82 | S30: 13 | T30: =R30-S30 -> 69 | AA30: In general, do you approve or disapprove of X as Y?
B31: May | F31: Gallup | R31: 87 | S31: 8 | T31: =R31-S31 -> 79 | AA31: In general, do you approve or disapprove of X as Y?
B32: Jun | F32: Gallup | R32: 86 | S32: 9 | T32: =R32-S32 -> 77 | AA32: In general, do you approve or disapprove of X as Y?
B33: Jul | F33: Gallup | R33: 78 | S33: 15 | T33: =R33-S33 -> 63 | AA33: In general, do you approve or disapprove of X as Y?
B34: Aug | F34: Gallup | R34: 82 | S34: 11 | T34: =R34-S34 -> 71 | AA34: In general, do you approve or disapprove of X as Y?
B35: Sep | F35: Gallup | R35: 82 | S35: 10 | T35: =R35-S35 -> 72 | AA35: In general, do you approve or disapprove of X as Y?
B36: Oct | F36: Gallup | R36: 83 | S36: 11 | T36: =R36-S36 -> 72 | AA36: In general, do you approve or disapprove of X as Y?
B37: Nov | F37: Gallup | R37: 91 | S37: 7 | T37: =R37-S37 -> 84 | AA37: In general, do you approve or disapprove of X as Y?
B38: Dec | F38: Gallup | R38: 93 | S38: 5 | T38: =R38-S38 -> 88 | AA38: In general, do you approve or disapprove of X as Y?
A39: 1943 | B39: Jan | F39: Gallup | R39: 91 | S39: 7 | T39: =R39-S39 -> 84 | AA39: In general, do you approve or disapprove of X as Y?
B40: Apr | F40: Gallup | R40: 90 | S40: 7 | T40: =R40-S40 -> 83 | AA40: In general, do you approve or disapprove of X as Y?
...

Sheet 45-50
A1: Year | B1: Month | C1: Fieldwork | E1: Published | F1: Polling | G1: Publisher | H1: Con | J1: Lab | L1: LD | N1: Con lead | Q1: Leader: | R1: Con good | S1: Con bad | T1: Con net | U1: Lab good | V1: Lab bad | W1: Lab net | X1: LD good | Y1: LD bad | Z1: LD net | AA1: Question | AB1: Con Best PM | AC1: Lab Best PM | AD1: LD Best PM | AE1: Question | AF1: Govt good | AG1: Govt bad | AH1: Govt net | AI1: Question
A2: 1945 | B2: Aug | F2: Gallup | U2: 66 | V2: 19 | W2: =U2-V2 -> 47 | AE2: Are you satisfied or dissatisfied with X as Y?
B3: Nov | F3: Gallup | AF3: 57 | AG3: 16 | AH3: =AF3-AG3 -> 41 | AI3: At the present time is the government doing its job well or badly?
A4: 1946 | B4: Jan | F4: Gallup | G4: News Chron | H4: 32 | J4: 52.5 | L4: 11 | N4: -20.5
B5: May | F5: Gallup | G5: News Chron | H5: 40 | I5: 8 | J5: 43.5 | K5: -9 | L5: 13 | M5: 2 | N5: -3.5 | O5: 17
B6: Jun | F6: Gallup | AF6: 42 | AG6: 45 | AH6: =AF6-AG6 -> -3 | AI6: In general, do you approve or disapprove of the government's record to date?
B7: Aug | F7: Gallup | AF7: 46 | AG7: 41 | AH7: =AF7-AG7 -> 5 | AI7: Are you satisfied or dissatisfied with the Government's record to date?
B8: Oct | F8: Gallup | U8: 53 | V8: 35 | W8: =U8-V8 -> 18 | AE8: Are you satisfied or dissatisfied with X as Y?
B9: Dec | F9: Gallup | U9: 52 | V9: 30 | W9: =U9-V9 -> 22 | AE9: Are you satisfied or dissatisfied with X as Y?
A10: 1947 | B10: Jan | F10: Gallup | G10: News Chron | H10: 41 | I10: 1 | J10: 44.5 | K10: 1 | L10: 12 | M10: -1 | N10: -3.5 | O10: 0
B11: Mar | F11: Gallup | G11: News Chron | H11: 43.5 | I11: 2.5 | J11: 43.5 | K11: -1 | L11: 10.5 | M11: -1.5 | N11: 0 | O11: 3.5 | U11: 46 | V11: 45 | W11: =U11-V11 -> 1 | AE11: Are you satisfied or dissatisfied with X as Y? | AF11: 39 | AG11: 54 | AH11: =AF11-AG11 -> -15 | AI11: Are you satisfied or dissatisfied with the Government's record to date?
B12: May | F12: Gallup | U12: 51 | V12: 36 | W12: =U12-V12 -> 15 | AE12: On the whole, do you approve or disapprove of X as Y? | AF12: 42 | AG12: 48 | AH12: =AF12-AG12 -> -6 | AI12: On the whole, are you satisfied or dissatisfied with the Government's record to date?
B13: Jun | F13: Gallup | G13: News Chron | H13: 42.5 | I13: -1 | J13: 42.5 | K13: -1 | L13: 12.5 | M13: 2 | N13: 0 | O13: 0
B14: Jul | F14: Gallup | G14: News Chron | H14: 42.5 | I14: 0 | J14: 42.5 | K14: 0 | L14: 12.5 | M14: 0 | N14: 0 | O14: 0 | U14: 51 | V14: 37 | W14: =U14-V14 -> 14 | AE14: On the whole, do you approve or disapprove of X as Y? | AF14: 38 | AG14: 52 | AH14: =AF14-AG14 -> -14 | AI14: On the whole, are you satisfied or dissatisfied with the Government's record to date?
B15: Aug | F15: Gallup | G15: News Chron | H15: 44.5 | I15: 2 | J15: 41 | K15: -1.5 | L15: 11 | M15: -1.5 | N15: 3.5 | O15: 3.5
B16: Sep | F16: Gallup | G16: News Chron | H16: 44.5 | I16: 0 | J16: 39.5 | K16: -1.5 | L16: 11.5 | M16: 0.5 | N16: 5 | O16: 1.5
B17: Oct | F17: Gallup | U17: 41 | V17: 46 | W17: =U17-V17 -> -5 | AE17: On the whole, do you approve or disapprove of X as Y?
B18: Nov | F18: Gallup | G18: News Chron | H18: 50.5 | I18: 6 | J18: 38 | K18: -1.5 | L18: 9 | M18: -2.5 | N18: 12.5 | O18: 7.5
B19: Dec | F19: Gallup | U19: 44 | V19: 46 | W19: =U19-V19 -> -2 | AE19: On the whole, do you approve or disapprove of X as Y? | AF19: 41 | AG19: 49 | AH19: =AF19-AG19 -> -8 | AI19: On the whole, are you satisfied or dissatisfied with the Government's record to date?
A20: 1948 | B20: Jan | F20: Gallup | G20: News Chron | H20: 44.5 | I20: -6 | J20: 43.5 | K20: 5.5 | L20: 10.5 | M20: 1.5 | N20: 1 | O20: -11.5 | U20: 45 | V20: 43 | W20: =U20-V20 -> 2 | AE20: On the whole, do you approve or disapprove of X as Y? | AF20: 44 | AG20: 47 | AH20: =AF20-AG20 -> -3 | AI20: On the whole, are you satisfied or dissatisfied with the Government's record to date?
B21: Feb | F21: Gallup | G21: News Chron | H21: 46 | I21: 1.5 | J21: 42 | K21: -1.5 | L21: 8.5 | M21: -2 | N21: 4 | O21: 3
B22: Mar | F22: Gallup | G22: News Chron | H22: 46 | I22: 0 | J22: 43 | K22: 1 | L22: 8.5 | M22: 0 | N22: 3 | O22: -1 | U22: 39 | V22: 48 | W22: =U22-V22 -> -9 | AE22: On the whole, do you approve or disapprove of X as Y? | AF22: 35 | AG22: 53 | AH22: =AF22-AG22 -> -18 | AI22: On the whole, are you satisfied or dissatisfied with the Government's record to date?
B23: Apr | F23: Gallup | G23: News Chron | H23: 42.5 | I23: -3.5 | J23: 41 | K23: -2 | L23: 10.5 | M23: 2 | N23: 1.5 | O23: -1.5
B24: May | F24: Gallup | G24: News Chron | H24: 45 | I24: 2.5 | J24: 41.5 | K24: 0.5 | L24: 11 | M24: 0.5 | N24: 3.5 | O24: 2
B25: Jul | F25: Gallup | G25: News Chron | H25: 48 | I25: 3 | J25: 39.5 | K25: -2 | L25: 9 | M25: -2 | N25: 8.5 | O25: 5 | U25: 40 | V25: 49 | W25: =U25-V25 -> -9 | AE25: On the whole, do you approve or disapprove of X as Y? | AF25: 36 | AG25: 54 | AH25: =AF25-AG25 -> -18 | AI25: On the whole, are you satisfied or dissatisfied with the Government's record to date?
B26: Aug | F26: Gallup | G26: News Chron | H26: 48 | I26: 0 | J26: 41 | K26: 1.5 | L26: 8.5 | M26: -0.5 | N26: 7 | O26: -1.5
B27: Sep | F27: Gallup | G27: News Chron | H27: 47.5 | I27: -0.5 | J27: 41.5 | K27: 0.5 | L27: 10 | M27: 1.5 | N27: 6 | O27: -1 | U27: 37 | V27: 46 | W27: =U27-V27 -> -9 | AE27: On the whole, do you approve or disapprove of X as Y? | AF27: 37 | AG27: 51 | AH27: =AF27-AG27 -> -14 | AI27: On the whole, are you satisfied or dissatisfied with the Government's record to date?
B28: Oct | F28: Gallup | G28: News Chron | H28: 46.5 | I28: -1 | J28: 41.5 | K28: 0 | L28: 9.5 | M28: -0.5 | N28: 5 | O28: -1
B29: Nov | F29: Gallup | G29: News Chron | H29: 46 | I29: -0.5 | J29: 43 | K29: 1.5 | L29: 8.5 | M29: -1 | N29: 3 | O29: -2 | U29: 45 | V29: 40 | W29: =U29-V29 -> 5 | AE29: On the whole, do you approve or disapprove of X as Y? | AF29: 43 | AG29: 46 | AH29: =AF29-AG29 -> -3 | AI29: On the whole, are you satisfied or dissatisfied with the Government's record to date?
A30: 1949 | B30: Jan | F30: Gallup | G30: News Chron | H30: 44 | I30: -2 | J30: 40.5 | K30: -2.5 | L30: 13 | M30: 4.5 | N30: 3.5 | O30: 0.5 | U30: 45 | V30: 44 | W30: =U30-V30 -> 1 | AE30: On the whole, do you approve or disapprove of X as Y? | AF30: 44 | AG30: 47 | AH30: =AF30-AG30 -> -3 | AI30: On the whole, are you satisfied or dissatisfied with the Government's record to date?
B31: Feb | F31: Gallup | G31: News Chron | H31: 44.5 | I31: 0.5 | J31: 43.5 | K31: 3 | L31: 9.5 | M31: -3.5 | N31: 1 | O31: -2.5
B32: Mar | F32: Gallup | G32: News Chron | H32: 41.5 | I32: -3 | J32: 43 | K32: -0.5 | L32: 13 | M32: 3.5 | N32: -1.5 | O32: -2.5 | U32: 47 | V32: 38 | W32: =U32-V32 -> 9 | AE32: On the whole, do you approve or disapprove of X as Y? | AF32: 46 | AG32: 43 | AH32: =AF32-AG32 -> 3 | AI32: On the whole, are you satisfied or dissatisfied with the Government's record to date?
B33: Apr | F33: Gallup | G33: News Chron | H33: 42 | I33: 0.5 | J33: 43.5 | K33: 0.5 | L33: 13 | M33: 0 | N33: -1.5 | O33: 0
B34: May | F34: Gallup | G34: News Chron | H34: 46 | I34: 4 | J34: 40 | K34: -3.5 | L34: 11 | M34: -2 | N34: 6 | O34: 7.5 | U34: 44 | V34: 42 | W34: =U34-V34 -> 2 | AE34: On the whole, do you approve or disapprove of X as Y? | AF34: 37 | AG34: 53 | AH34: =AF34-AG34 -> -16 | AI34: On the whole, are you satisfied or dissatisfied with the Government's record to date?
B35: Jun | F35: Gallup | G35: News Chron | H35: 46 | I35: 0 | J35: 41.5 | K35: 1.5 | L35: 10 | M35: -1 | N35: 4.5 | O35: -1.5
B36: Jul | F36: Gallup | G36: News Chron | H36: 44.5 | I36: -1.5 | J36: 40.5 | K36: -1 | L36: 12.5 | M36: 2.5 | N36: 4 | O36: -0.5 | U36: 46 | V36: 42 | W36: =U36-V36 -> 4 | AE36: On the whole, do you approve or disapprove of X as Y? | AF36: 39 | AG36: 48 | AH36: =AF36-AG36 -> -9 | AI36: On the whole, are you satisfied or dissatisfied with the Government's record to date?
B37: Aug | F37: Gallup | G37: News Chron | H37: 46.5 | I37: 2 | J37: 40.5 | K37: 0 | L37: 11.5 | M37: -1 | N37: 6 | O37: 2
B38: Sep | F38: Gallup | G38: News Chron | H38: 46 | I38: -0.5 | J38: 40 | K38: -0.5 | L38: 12 | M38: 0.5 | N38: 6 | O38: 0 | U38: 45 | V38: 43 | W38: =U38-V38 -> 2 | AE38: On the whole, do you approve or disapprove of X as Y? | AF38: 36 | AG38: 53 | AH38: =AF38-AG38 -> -17 | AI38: On the whole, are you satisfied or dissatisfied with the Government's record to date?
B39: Oct | F39: Gallup | G39: News Chron | H39: 45.5 | I39: -0.5 | J39: 39.5 | K39: -0.5 | L39: 12.5 | M39: 0.5 | N39: 6 | O39: 0
B40: Oct | H40: 50 | J40: 39 | L40: 8 | P40: From 1950 GE book
...

Sheet 50-51
A1: Year | B1: Month | C1: Fieldwork | E1: Published | F1: Polling | G1: Publisher | H1: Con | J1: Lab | L1: LD | N1: Con lead | Q1: Leader: | R1: Con good | S1: Con bad | T1: Con net | U1: Lab good | V1: Lab bad | W1: Lab net | X1: LD good | Y1: LD bad | Z1: LD net | AA1: Question | AC1: Govt good | AD1: Govt bad | AE1: Govt net | AF1: Question
A2: 1950 | B2: Mar | F2: Gallup | G2: News Chron | H2: 43.5 | J2: 45.5 | L2: 8.5 | N2: =H2-J2 -> -2
B3: Apr | F3: Gallup | G3: News Chron | H3: 45.5 | I3: 2 | J3: 47 | K3: 1.5 | L3: 7 | M3: -1.5 | N3: =H3-J3 -> -1.5 | O3: 0.5
B4: May | F4: Gallup | G4: News Chron | H4: 43.5 | I4: -2 | J4: 46.5 | K4: -0.5 | L4: 9.5 | M4: 2.5 | N4: =H4-J4 -> -3 | O4: -1.5 | U4: 50 | V4: 39 | W4: =U4-V4 -> 11 | AA4: On the whole, do you approve or disapprove of X as Y? | AC4: 41 | AD4: 49 | AE4: =AC4-AD4 -> -8 | AF4: On the whole, are you satisfied or dissatisfied with the Government's record to date?
B5: Jun | F5: Gallup | G5: News Chron | H5: 43.5 | I5: 0 | J5: 46 | K5: -0.5 | L5: 9 | M5: -0.5 | N5: =H5-J5 -> -2.5 | O5: 0.5
B6: Jul | F6: Gallup | G6: News Chron | H6: 42 | I6: -1.5 | J6: 43.5 | K6: -2.5 | L6: 11 | M6: 2 | N6: =H6-J6 -> -1.5 | O6: 1
B7: Aug | F7: Gallup | G7: News Chron | H7: 44.5 | I7: 2.5 | J7: 46 | K7: 2.5 | L7: 8.5 | M7: -2.5 | N7: =H7-J7 -> -1.5 | O7: 0 | U7: 49 | V7: 43 | W7: =U7-V7 -> 6 | AA7: On the whole, do you approve or disapprove of X as Y? | AC7: 44 | AD7: 46 | AE7: =AC7-AD7 -> -2 | AF7: On the whole, are you satisfied or dissatisfied with the Government's record to date?
B8: Sep | F8: Gallup | G8: News Chron | H8: 43 | I8: -1.5 | J8: 45.5 | K8: -0.5 | L8: 10 | M8: 1.5 | N8: =H8-J8 -> -2.5 | O8: -1
B9: Oct | F9: Gallup | G9: News Chron | H9: 42.5 | I9: -0.5 | J9: 45 | K9: -0.5 | L9: 10 | M9: 0 | N9: =H9-J9 -> -2.5 | O9: 0 | U9: 47 | V9: 40 | W9: =U9-V9 -> 7 | AA9: On the whole, do you approve or disapprove of X as Y? | AC9: 45 | AD9: 45 | AE9: =AC9-AD9 -> 0 | AF9: On the whole, are you satisfied or dissatisfied with the Government's record to date?
B10: Oct | G10: DE | H10: 45.5 | J10: 45.5 | L10: 8 | N10: =H10-J10 -> 0
B11: Nov | F11: Gallup | G11: News Chron | P11: Poll conducted but results lost by Gallup
B12: Nov | G12: DE | H12: 47 | I12: 1.5 | J12: 45 | K12: -0.5 | L12: 7.5 | M12: -0.5 | N12: =H12-J12 -> 2 | O12: 2
B13: Dec | F13: Gallup | G13: News Chron | H13: 43 | J13: 44 | L13: 11.5 | N13: =H13-J13 -> -1 | U13: 49 | V13: 38 | W13: =U13-V13 -> 11 | AA13: On the whole, do you approve or disapprove of X as Y? | AC13: 38 | AD13: 51 | AE13: =AC13-AD13 -> -13 | AF13: Are you satisfied or dissatisfied with the Government's record to date?
B14: Dec | G14: DE | H14: 47.5 | I14: 0.5 | J14: 44.5 | K14: -0.5 | L14: 7.5 | M14: 0 | N14: =H14-J14 -> 3 | O14: 1
A15: 1951 | B15: Jan | F15: Gallup | G15: News Chron | H15: 51 | I15: 8 | J15: 38 | K15: -6 | L15: 10 | M15: -1.5 | N15: =H15-J15 -> 13 | O15: 14
B16: Jan | G16: DE | H16: 48 | I16: 0.5 | J16: 44 | K16: -0.5 | L16: 7 | M16: -0.5 | N16: =H16-J16 -> 4 | O16: 1
B17: Feb | G17: DE | H17: 50.5 | I17: 2.5 | J17: 40.5 | K17: -3.5 | L17: 8 | M17: 1 | N17: =H17-J17 -> 10 | O17: 6
B18: Feb | F18: Gallup | G18: News Chron | H18: 51.5 | I18: =H18-H17 -> 1 | J18: 37.5 | K18: =J18-J17 -> -3 | L18: 9.5 | M18: =L18-L17 -> 1.5 | N18: =H18-J18 -> 14 | O18: =N18-N17 -> 4 | U18: 44 | V18: 47 | W18: =U18-V18 -> -3 | AA18: Do you approve or disapprove of X as Y? | AC18: 31 | AD18: 60 | AE18: =AC18-AD18 -> -29 | AF18: Are you satisfied with the Government's record to date?
B19: Feb | C19: 17-25 | D19: 18676 | G19: DE | H19: 52 | I19: =H19-H18 -> 0.5 | J19: 39.5 | K19: =J19-J18 -> 2 | L19: 7.5 | M19: =L19-L18 -> -2 | N19: =H19-J19 -> 12.5 | O19: =N19-N18 -> -1.5
B20: Mar | F20: Gallup | G20: News Chron | H20: 51 | I20: -0.5 | J20: 36.5 | K20: -1 | L20: 10.5 | M20: 1 | N20: =H20-J20 -> 14.5 | O20: 0.5
B21: Mar | C21: 3-10 | D21: 18690 | G21: DE | H21: 52 | I21: 0 | J21: 39 | K21: -0.5 | L21: 8 | M21: 0.5 | N21: =H21-J21 -> 13 | O21: 0.5
B22: Apr | F22: Gallup | G22: News Chron | H22: 50.5 | I22: -0.5 | J22: 38.5 | K22: 2 | L22: 9 | M22: -1.5 | N22: =H22-J22 -> 12 | O22: -2.5 | U22: 49 | V22: 40 | W22: =U22-V22 -> 9 | AA22: Do you approve or disapprove of X as Y? | AC22: 32 | AD22: 59 | AE22: =AC22-AD22 -> -27 | AF22: Are you satisfied or dissatisfied with the Government's record to date?
B23: May | F23: Gallup | G23: News Chron | H23: 49 | I23: -1.5 | J23: 40 | K23: 1.5 | L23: 9.5 | M23: 0.5 | N23: =H23-J23 -> 9 | O23: -3 | U23: 57 | V23: 35 | W23: =U23-V23 -> 22 | AA23: Do you approve or disapprove of X as Y? | AC23: 35 | AD23: 56 | AE23: =AC23-AD23 -> -21 | AF23: Are you satisfied or dissatisfied with the Government's record to date?
B24: Jun | F24: Gallup | G24: News Chron | H24: 48 | I24: -1 | J24: 41 | K24: 1 | L24: 10 | M24: 0.5 | N24: =H24-J24 -> 7 | O24: -2
B25: Jul | F25: Gallup | G25: News Chron | H25: 49 | I25: 1 | J25: 39 | K25: -2 | L25: 10.5 | M25: 0.5 | N25: =H25-J25 -> 10 | O25: 3 | U25: 43 | V25: 43 | W25: =U25-V25 -> 0 | AA25: Do you approve or disapprove of X as Y? | AC25: 31 | AD25: 56 | AE25: =AC25-AD25 -> -25 | AF25: Are you satisfied or dissatisfied with the Government's record to date?
B26: Aug | F26: Gallup | G26: News Chron | H26: 50.5 | I26: 1.5 | J26: 38 | K26: -1 | L26: 10.5 | M26: 0 | N26: =H26-J26 -> 12.5 | O26: 2.5
B27: Sep | C27: 26 | D27: 18897 | F27: Gallup | G27: News Chron | H27: 52 | I27: 1.5 | J27: 41 | K27: 3 | L27: 6.5 | M27: -4 | N27: =H27-J27 -> 11 | O27: -1.5 | U27: 44 | V27: 41 | W27: =U27-V27 -> 3 | AA27: Do you approve or disapprove of X as Y? | AC27: 35 | AD27: 54 | AE27: =AC27-AD27 -> -19 | AF27: Are you satisfied or dissatisfied with the Government's record to date?
B28: Oct | C28: 3 | D28: 18904 | F28: Gallup | G28: News Chron | H28: 50.5 | I28: -1.5 | J28: 43.5 | K28: 2.5 | L28: 5.5 | M28: -1 | N28: =H28-J28 -> 7 | O28: -4
B29: Oct | C29: 10 | D29: 18911 | F29: Gallup | G29: News Chron | H29: 50.5 | I29: 0 | J29: 44 | K29: 0.5 | L29: 4.5 | M29: -1 | N29: =H29-J29 -> 6.5 | O29: -4.5
B30: Oct | C30: 17 | D30: 18918 | F30: Gallup | G30: News Chron | H30: 50 | I30: -0.5 | J30: 45.5 | K30: 1.5 | L30: 4.5 | M30: 0 | N30: =H30-J30 -> 4.5 | O30: -2.5
B31: Oct | C31: 19 | D31: 18920 | F31: Gallup | H31: 50 | I31: 0 | J31: 46.5 | K31: 1 | L31: 3 | M31: -1.5 | N31: =H31-J31 -> 3.5 | O31: -1
B32: Oct | C32: 19 | D32: 18920 | F32: Research Serv Ltd | G32: DG | H32: 50 | J32: 43 | L32: 6.7 | N32: =H32-J32 -> 7
B33: Oct | C33: 19-23 | D33: 18920 | G33: DE | H33: 50 | J33: 46 | L33: 3.5 | N33: =H33-J33 -> 4
B34: Oct | C34: 22 | D34: 18923 | F34: Gallup | G34: News Chron | H34: 49.5 | J34: 47 | L34: 3 | N34: =H34-J34 -> 2.5
E36: 25 | F36: Result | H36: 47.8 | J36: 49.4 | L36: 2.6 | N36: =H36-J36 -> -1.6

Sheet 51-55
A1: Year | B1: Month | C1: Fieldwork | E1: Published | F1: Polling | G1: Publisher | H1: Con | J1: Lab | L1: LD | N1: Con lead | Q1: Leader: | R1: Con good | S1: Con bad | T1: Con net | U1: Lab good | V1: Lab bad | W1: Lab net | X1: LD good | Y1: LD bad | Z1: LD net | AA1: Question | AC1: Govt good | AD1: Govt bad | AE1: Govt net | AF1: Question
A2: 1951 | B2: Nov | F2: Gallup | G2: News Chron | P2: Poll conducted but results lost by Gallup
B3: Dec | F3: Gallup | G3: News Chron | H3: 47 | J3: 45 | L3: 6.5 | N3: =H3-J3 -> 2 | R3: 55 | S3: 37 | T3: =R3-S3 -> 18 | AA3: Do you approve or disapprove of X as Y? | AC3: 44 | AD3: 29 | AE3: =AC3-AD3 -> 15 | AF3: Are you satisfied or dissatisfied with the Government's record to date?
A4: 1952 | B4: Jan | F4: Gallup | G4: News Chron | H4: 44.5 | I4: -2.5 | J4: 48 | K4: 3 | L4: 6 | M4: -0.5 | N4: =H4-J4 -> -3.5 | O4: -5.5 | R4: 53
B5: Feb | F5: Gallup | G5: News Chron | H5: 41 | I5: -3.5 | J5: 47 | K5: -1 | L5: 10.5 | M5: 4.5 | N5: =H5-J5 -> -6 | O5: -2.5
B6: Mar | F6: Gallup | G6: News Chron | H6: 41.5 | I6: 0.5 | J6: 48 | K6: 1 | L6: 9.5 | M6: -1 | N6: =H6-J6 -> -6.5 | O6: -0.5
B7: Apr | F7: Gallup | G7: News Chron | H7: 43.5 | I7: 2 | J7: 49 | K7: 1 | N7: =H7-J7 -> -5.5 | P7: Poll conducted but results lost by Gallup. Results from Butler 1952 book
B8: May | F8: Gallup | G8: News Chron | H8: 43.5 | I8: 0 | J8: 49 | K8: 0 | L8: 7 | N8: =H8-J8 -> -5.5 | R8: 51 | S8: 42 | T8: =R8-S8 -> 9 | AA8: Do you approve or disapprove of X as Y? | AC8: 40 | AD8: 48 | AE8: =AC8-AD8 -> -8 | AF8: Are you satisfied or dissatisfied with the Government's record to date?
B9: Jun | F9: Gallup | G9: News Chron | H9: 40.5 | I9: -3 | J9: 49 | K9: 0 | L9: 9.5 | M9: 2.5 | N9: =H9-J9 -> -8.5 | O9: -3
B10: Jul | F10: Gallup | G10: News Chron | H10: 40 | I10: -0.5 | J10: 50 | K10: 1 | L10: 8.5 | M10: -1 | N10: =H10-J10 -> -10 | O10: -1.5
B11: Aug | F11: Gallup | G11: News Chron | H11: 40 | I11: 0 | J11: 48 | K11: -2 | L11: 10.5 | M11: 2 | N11: =H11-J11 -> -8 | O11: 2 | R11: 48 | S11: 44 | T11: =R11-S11 -> 4 | AA11: Do you approve or disapprove of X as Y? | AC11: 44 | AD11: 44 | AE11: =AC11-AD11 -> 0 | AF11: Are you satisfied or dissatisfied with the Government's record to date?
B12: Sep | F12: Gallup | G12: News Chron | H12: 41 | I12: 1 | J12: 48.5 | K12: 0.5 | L12: 9 | M12: -1.5 | N12: =H12-J12 -> -7.5 | O12: 0.5
B13: Oct | F13: Gallup | G13: News Chron | H13: 41.5 | I13: 0.5 | J13: 48 | K13: -0.5 | L13: 9 | M13: 0 | N13: =H13-J13 -> -6.5 | O13: 1
B14: Nov | F14: Gallup | G14: News Chron | H14: 43.5 | I14: 2 | J14: 46.5 | K14: -1.5 | L14: 9 | M14: 0 | N14: =H14-J14 -> -3 | O14: 3.5 | R14: 51 | S14: 39 | T14: =R14-S14 -> 12 | AA14: Do you approve or disapprove of X as Y? | AC14: 47 | AD14: 33 | AE14: =AC14-AD14 -> 14 | AF14: Are you satisfied or dissatisfied with the Government's record to date?
B15: Dec | F15: Gallup | G15: News Chron | H15: 44 | I15: 0.5 | J15: 45.5 | K15: -1 | L15: 9.5 | M15: 0.5 | N15: =H15-J15 -> -1.5 | O15: 1.5
A16: 1953 | B16: Jan | F16: Gallup | G16: News Chron | H16: 42.5 | I16: -1.5 | J16: 46 | K16: 0.5 | L16: 10 | M16: 0.5 | N16: =H16-J16 -> -3.5 | O16: -2 | R16: 51 | S16: 40 | T16: =R16-S16 -> 11 | AA16: Do you approve or disapprove of X as Y? | AC16: 46 | AD16: 38 | AE16: =AC16-AD16 -> 8 | AF16: Are you satisfied or dissatisfied with the Government's record to date?
B17: Feb | F17: Gallup | G17: News Chron | H17: 42.5 | I17: 0 | J17: 46 | K17: 0 | L17: 10 | M17: 0 | N17: =H17-J17 -> -3.5 | O17: 0
B18: Mar | F18: Gallup | G18: News Chron | H18: 46.5 | I18: 4 | J18: 44.5 | K18: -1.5 | L18: 8 | M18: -2 | N18: =H18-J18 -> 2 | O18: 5.5
B19: Apr | F19: Gallup | G19: News Chron | H19: 47 | I19: 0.5 | J19: 45 | K19: 0.5 | L19: 7.5 | M19: -0.5 | N19: =H19-J19 -> 2 | O19: 0 | AC19: 60 | AD19: 27 | AE19: =AC19-AD19 -> 33 | AF19: Are you satisfied or dissatisfied with the Government's record to date?
B20: May | F20: Gallup | G20: News Chron | H20: 47 | I20: 0 | J20: 45 | K20: 0 | L20: 7.5 | M20: 0 | N20: =H20-J20 -> 2 | O20: 0
B21: Jun | F21: Gallup | G21: News Chron | H21: 46 | I21: -1 | J21: 46 | K21: 1 | L21: 7 | M21: -0.5 | N21: =H21-J21 -> 0 | O21: -2
B22: Jul | F22: Gallup | G22: News Chron | P22: Poll conducted but results lost by Gallup
B23: Aug | F23: Gallup | G23: News Chron | H23: 45 | I23: =H23-H21 -> -1 | J23: 46 | K23: =J23-J21 -> 0 | L23: 8 | M23: =L23-L21 -> 1 | N23: =H23-J23 -> -1 | O23: =N23-N21 -> -1 | AC23: 49 | AD23: 35 | AE23: =AC23-AD23 -> 14 | AF23: Are you satisfied or dissatisfied with the Government's record to date?
B24: Sep | F24: Gallup | G24: News Chron | H24: 44.5 | I24: -0.5 | J24: 47.5 | K24: 1.5 | L24: 7 | M24: -1 | N24: =H24-J24 -> -3 | O24: -2
B25: Oct | F25: Gallup | G25: News Chron | H25: 45 | I25: 0.5 | J25: 47.5 | K25: 0 | L25: 7 | M25: 0 | N25: =H25-J25 -> -2.5 | O25: 0.5 | R25: 56 | S25: 34 | T25: =R25-S25 -> 22 | AA25: Do you approve or disapprove of X as Y? | AC25: 54 | AD25: 31 | AE25: =AC25-AD25 -> 23 | AF25: Are you satisfied or dissatisfied with the Government's record to date?
B26: Nov | F26: Gallup | G26: News Chron | P26: Poll conducted but results lost by Gallup
B27: Dec | F27: Gallup | G27: News Chron | H27: 45 | J27: 47 | L27: 7 | N27: =H27-J27 -> -2
A28: 1954 | B28: Jan | C28: 21-31 | D28: 19745 | F28: Gallup | G28: News Chron | H28: 45.5 | I28: 0.5 | J28: 46.5 | K28: -0.5 | L28: 7 | M28: 0 | N28: =H28-J28 -> -1 | O28: 1 | AC28: 50 | AD28: 32 | AE28: =AC28-AD28 -> 18 | AF28: Are you satisfied or dissatisfied with the Government's record to date?
B29: Feb | C29: 18-28 | D29: 19773 | F29: Gallup | G29: News Chron | H29: 45 | I29: -0.5 | J29: 44.5 | K29: -2 | L29: 9 | M29: 2 | N29: =H29-J29 -> 0.5 | O29: 1.5
B30: Feb | C30: 26 | D30: 19781 | F30: Gallup | G30: News Chron | H30: 45.5 | I30: 0.5 | J30: 47 | K30: 2.5 | L30: 7 | M30: -2 | N30: =H30-J30 -> -1.5 | O30: -2
B31: Mar | C31: 20-31 | D31: 19803 | F31: Gallup | G31: News Chron | H31: 46.5 | I31: 1 | J31: 45.5 | K31: -1.5 | L31: 7 | M31: 0 | N31: =H31-J31 -> 1 | O31: 2.5
B32: Mar | C32: 31 | D32: 19814 | F32: Gallup | G32: News Chron | H32: 46 | I32: -0.5 | J32: 45.5 | K32: 0 | L32: 7 | M32: 0 | N32: =H32-J32 -> 0.5 | O32: -0.5
B33: Apr | C33: 16-27 | D33: 19830 | F33: Gallup | G33: News Chron | H33: 46.5 | I33: 0.5 | J33: 46 | K33: 0.5 | L33: 7 | M33: 0 | N33: =H33-J33 -> 0.5 | O33: 0 | R33: 48 | S33: 44 | T33: =R33-S33 -> 4 | AA33: Do you approve or disapprove of X as Y?
B34: May | F34: Gallup | G34: News Chron | H34: 45.5 | I34: -1 | J34: 47.5 | K34: 1.5 | L34: 6.5 | M34: -0.5 | N34: =H34-J34 -> -2 | O34: -2.5
B35: Jun | F35: Gallup | G35: News Chron | H35: 45 | I35: -0.5 | J35: 47.5 | K35: 0 | L35: 7 | M35: 0.5 | N35: =H35-J35 -> -2.5 | O35: -0.5 | AC35: 47 | AD35: 33 | AE35: =AC35-AD35 -> 14 | AF35: Are you satisfied or dissatisfied with the Government's record to date?
B36: Jul | F36: Gallup | G36: News Chron | P36: Poll conducted but results lost by Gallup
B37: Aug | F37: Gallup | G37: News Chron | H37: 42.5 | J37: 48.5 | L37: 8 | N37: =H37-J37 -> -6
B38: Sep | F38: Gallup | G38: News Chron | H38: 43 | I38: 0.5 | J38: 48 | K38: -0.5 | L38: 8 | M38: 0 | N38: =H38-J38 -> -5 | O38: 1
B39: Oct | F39: Gallup | G39: News Chron | H39: 45 | I39: 2 | J39: 45.5 | K39: -2.5 | L39: 8 | M39: 0 | N39: =H39-J39 -> -0.5 | O39: 4.5
B40: Nov | F40: Gallup | G40: News Chron | H40: 46 | I40: 1 | J40: 47 | K40: 1.5 | L40: 6 | M40: -2 | N40: =H40-J40 -> -1 | O40: -0.5
...

Sheet 55-59
A1: Year | B1: Month | C1: Fieldwork | E1: Published | F1: Polling | G1: Publisher | H1: Con | J1: Lab | L1: LD | N1: Con lead | Q1: Leader: | R1: Con good | S1: Con bad | T1: Con net | U1: Lab good | V1: Lab bad | W1: Lab net | X1: LD good | Y1: LD bad | Z1: LD net | AA1: Question | AB1: Con Best PM | AC1: Lab Best PM | AD1: LD Best PM | AE1: Question | AF1: Govt good | AG1: Govt bad | AH1: Govt net | AI1: Question
A2: 1955 | B2: Jun | F2: Gallup | G2: News Chron | P2: Non-Gallup figures recaclulated to exclude "don't know" and rounded to nearest whole number where required
B3: Jul | C3: 2-13 | D3: 20272 | F3: Gallup | G3: News Chron | H3: 47 | J3: 43 | L3: 9 | N3: =H3-J3 -> 4 | R3: 68 | S3: 17 | T3: =R3-S3 -> 51 | AA3: For Con: Are you satisfied or dissatisfied with X as Y?
B4: Aug | F4: Gallup | G4: News Chron | H4: 44.5 | I4: -2.5 | J4: 47.5 | K4: 4.5 | L4: 7 | M4: -2 | N4: =H4-J4 -> -3 | O4: -7
B5: Sep | C5: 9-19 | D5: 20341 | F5: Gallup | G5: News Chron | H5: 48 | I5: 3.5 | J5: 44 | K5: -3.5 | L5: 7 | M5: 0 | N5: =H5-J5 -> 4 | O5: 7 | R5: 70 | S5: 16 | T5: =R5-S5 -> 54 | AA5: For Con: Are you satisfied or dissatisfied with X as Y?
B6: Oct | C6: 19-26 | D6: 20381 | F6: Gallup | G6: News Chron | H6: 46.5 | I6: -1.5 | J6: 44.5 | K6: 0.5 | L6: 8 | M6: 1 | N6: =H6-J6 -> 2 | O6: -2 | R6: 63 | S6: 21 | T6: =R6-S6 -> 42 | AA6: For Con: Are you satisfied or dissatisfied with X as Y?
B7: Dec | C7: 24-4 | D7: 20447 | F7: Gallup | G7: News Chron | H7: 44.5 | I7: -2 | J7: 45.5 | K7: 1 | L7: 9 | M7: 1 | N7: =H7-J7 -> -1 | O7: -3 | R7: 61 | S7: 26 | T7: =R7-S7 -> 35 | AA7: For Con: Are you satisfied or dissatisfied with X as Y?
B8: Dec | C8: 17-30 | D8: 20440 | F8: Gallup | G8: News Chron | H8: 45.5 | I8: 1 | J8: 46.5 | K8: 1 | L8: 7.5 | M8: -1.5 | N8: =H8-J8 -> -1 | O8: 0 | R8: 60 | S8: 24 | T8: =R8-S8 -> 36 | AA8: For Con: Are you satisfied or dissatisfied with X as Y? | AF8: 44 | AG8: 40 | AH8: =AF8-AG8 -> 4 | AI8: Do you approve or disapprove of the government's record to date?
A9: 1956 | B9: Jan | C9: 14-26 | D9: 20468 | F9: Gallup | G9: News Chron | H9: 45.5 | I9: 0 | J9: 46.5 | K9: 0 | L9: 7.5 | M9: 0 | N9: =H9-J9 -> -1 | O9: 0
B10: Feb | C10: 11-20 | D10: 20496 | F10: Gallup | G10: News Chron | H10: 44 | I10: -1.5 | J10: 46 | K10: -0.5 | L10: 9 | M10: 1.5 | N10: =H10-J10 -> -2 | O10: -1 | R10: 50 | S10: 34 | T10: =R10-S10 -> 16 | AA10: For Con: Are you satisfied or dissatisfied with X as Y?
B11: Apr | C11: 24-4 | D11: 20569 | F11: Gallup | G11: News Chron | H11: 44.5 | I11: 0.5 | J11: 47.5 | K11: 1.5 | L11: 7 | M11: -2 | N11: =H11-J11 -> -3 | O11: -1 | R11: 45 | S11: 37 | T11: =R11-S11 -> 8 | AA11: For Con: Are you satisfied or dissatisfied with X as Y? | AF11: 34 | AG11: 43 | AH11: =AF11-AG11 -> -9 | AI11: Do you approve or disapprove of the government's record to date?
B12: Apr | C12: 20-29 | D12: 20565 | F12: Gallup | G12: News Chron | H12: 43 | I12: -1.5 | J12: 48 | K12: 0.5 | L12: 8 | M12: 1 | N12: =H12-J12 -> -5 | O12: -2 | R12: 41
B13: May | C13: 19-27 | D13: 20594 | F13: Gallup | G13: News Chron | H13: 43 | I13: 0 | J13: 47 | K13: -1 | L13: 9 | M13: 1 | N13: =H13-J13 -> -4 | O13: 1 | R13: 54 | U13: 42 | V13: 24 | W13: =U13-V13 -> 18 | AA13: For Con:? For Lab: Do you think that X is or is not a good leader of Y? | AF13: 40 | AG13: 51 | AH13: =AF13-AG13 -> -11 | AI13: Do you approve or disapprove of the government's record to date?
B14: Jun | F14: Gallup | G14: News Chron | P14: Poll conducted but results lost by Gallup
B15: Jul | C15: 13-23 | D15: 20649 | F15: Gallup | G15: News Chron | H15: 42 | J15: 49 | L15: 8 | N15: =H15-J15 -> -7 | R15: 50 | S15: 33 | T15: =R15-S15 -> 17 | U15: 46 | V15: 18 | W15: =U15-V15 -> 28 | AA15: For Con: Are you satisfied with X as Y? For Lab: Do you think that X is, or is not, proving to be a good leader of Y? | AF15: 36 | AG15: 46 | AH15: =AF15-AG15 -> -10 | AI15: Do you approve or disapprove of the government's record to date?
B16: Aug | C16: 16-24 | D16: 20683 | F16: Gallup | G16: News Chron | H16: 43.5 | I16: 1.5 | J16: 49.5 | K16: 0.5 | L16: 6 | M16: -2 | N16: =H16-J16 -> -6 | O16: 1
B17: Sep | C17: 7-18 | D17: 20705 | F17: Gallup | G17: News Chron | H17: 43 | I17: -0.5 | J17: 46.5 | K17: -3 | L17: 10 | M17: 4 | N17: =H17-J17 -> -3.5 | O17: 2.5 | R17: 51 | S17: 34 | T17: =R17-S17 -> 17 | U17: 53 | V17: 17 | W17: =U17-V17 -> 36 | AA17: For Con: Are you satisfied or dissatisfied with X as Y? For Lab: Do you think that X is, or is not, proving to be a good leader of Y?
B18: Oct | F18: Gallup | G18: News Chron | H18: 42.5 | I18: -0.5 | J18: 47 | K18: 0.5 | L18: 9.5 | M18: -0.5 | N18: =H18-J18 -> -4.5 | O18: -1 | R18: 47 | S18: 36 | T18: =R18-S18 -> 11 | AA18: For Con: Are you satisfied or dissatisfied with X as Y?
B19: Nov | C19: 10-11 | D19: 20769 | F19: Gallup | G19: News Chron | H19: 46 | I19: 3.5 | J19: 45 | K19: -2 | L19: 8 | M19: -1.5 | N19: =H19-J19 -> 1 | O19: 5.5 | R19: 57 | S19: 35 | T19: =R19-S19 -> 22 | AA19: For Con: Are you satisfied or dissatisfied with X as Y?
B20: Nov | C20: 22-25 | D20: 20781 | F20: Gallup | G20: News Chron | H20: 45 | I20: -1 | J20: 46 | K20: 1 | L20: 8.5 | M20: 0.8 | N20: =H20-J20 -> -1 | O20: -2 | R20: 52 | AA20: For Con: Are you satisfied or dissatisfied with X as Y?
B21: Dec | C21: 1-2 | D21: 20790 | F21: Gallup | G21: News Chron | H21: 45 | I21: 0 | J21: 46 | K21: 0 | L21: 8 | M21: -0.8 | N21: =H21-J21 -> -1 | O21: 0 | R21: 56 | S21: 33 | T21: =R21-S21 -> 23 | U21: 44 | V21: 30 | W21: =U21-V21 -> 14 | AA21: For Con: Are you satisfied or dissatisfied with X as Y? For Lab: Do you think that X is, or is not, proving to be a good leader of Y?
A22: 1957 | B22: Jan | C22: 12-13 | D22: 20832 | F22: Gallup | G22: News Chron | H22: 43.5 | I22: -1.5 | J22: 48.5 | K22: 2.5 | L22: 7 | M22: -1 | N22: =H22-J22 -> -5 | O22: -4 | R22: 50 | S22: 25 | T22: =R22-S22 -> 25 | U22: 55 | V22: 25 | W22: =U22-V22 -> 30 | AA22: For Con: Do you approve or disapprove of the appointment of X as Y? For Lab: How would you rate X?
B23: Feb | F23: Gallup | G23: News Chron | H23: 42 | I23: -1.5 | J23: 48 | K23: -0.5 | L23: 8.5 | M23: 1.5 | N23: =H23-J23 -> -6 | O23: -1
B24: Mar | C24: 15-22 | D24: 20894 | F24: Gallup | G24: News Chron | H24: 40 | I24: -2 | J24: 51.5 | K24: 3.5 | L24: 7.5 | M24: -1 | N24: =H24-J24 -> -11.5 | O24: -5.5 | R24: 45 | S24: 23 | T24: =R24-S24 -> 22 | AA24: For Con: Are you satisfied or dissatisfied with X as Y?
B25: Apr | C25: 12-16 | D25: 20922 | F25: Gallup | G25: News Chron | H25: 41 | I25: 1 | J25: 51 | K25: -0.5 | L25: 7 | M25: -0.5 | N25: =H25-J25 -> -10 | O25: 1.5 | R25: 44 | S25: 34 | T25: =R25-S25 -> 10 | AA25: For Con: Are you satisfied or dissatisfied with X as Y?
B26: Jun | C26: 24-1 | D26: 20995 | F26: Gallup | G26: News Chron | H26: 41.5 | I26: 0.5 | J26: 50 | K26: -1 | L26: 7.5 | M26: 0.5 | N26: =H26-J26 -> -8.5 | O26: 1.5 | R26: 54 | S26: 27 | T26: =R26-S26 -> 27 | U26: 41 | V26: 27 | W26: =U26-V26 -> 14 | AA26: For Con: Are you satisfied or dissatisfied with X as Y? For Lab: Do you think that X is or is not proving to be a good leader of Y?
B27: Jun | F27: Gallup | G27: News Chron | P27: Poll conducted but results lost by Gallup
B28: Jul | C28: 5-11 | D28: 21006 | F28: Gallup | G28: News Chron | H28: 41.5 | J28: 49.5 | L28: 8 | N28: =H28-J28 -> -8
B29: Aug | C29: 16-27 | D29: 21048 | F29: Gallup | G29: News Chron | H29: 41.5 | I29: 0 | J29: 49 | K29: -0.5 | L29: 8.5 | M29: 0.5 | N29: =H29-J29 -> -7.5 | O29: 0.5
B30: Aug | C30: 29-10 | D30: 21061 | F30: Gallup | G30: News Chron | H30: 40.5 | I30: -1 | J30: 48.5 | K30: -0.5 | L30: 10 | M30: 1.5 | N30: =H30-J30 -> -8 | O30: -0.5
B31: Sep | C31: 19-25 | D31: 21082 | F31: Gallup | G31: News Chron | H31: 33.5 | I31: -7 | J31: 52 | K31: 3.5 | L31: 14 | M31: 4 | N31: =H31-J31 -> -18.5 | O31: -10.5 | U31: 39 | V31: 23 | W31: =U31-V31 -> 16 | X31: 19 | Y31: 7 | Z31: =X31-Y31 -> 12 | AA31: For Lab: Do you think that X is or is not proving a good leader of Y? For Lib: Do you think X is or is not doing a good job as leader of Y?
B32: Oct | C32: 4-8 | D32: 21097 | F32: Gallup | G32: News Chron | H32: 37 | I32: 3.5 | J32: 49 | K32: -3 | L32: 13 | M32: -1 | N32: =H32-J32 -> -12 | O32: 6.5 | R32: 44 | S32: 34 | T32: =R32-S32 -> 10 | AA32: For Con: Are you satisfied or dissatisfied with X as Y? | AB32: 44 | AC32: 29 | AE32: Who do you think would do the better job as Prime Minister, X or Y? | AF32: 37 | AG32: 42 | AH32: =AF32-AG32 -> -5 | AI32: Do you approve or disapprove of the government's record to date?
B33: Nov | C33: 2-6 | D33: 21126 | F33: Gallup | G33: News Chron | H33: 36 | I33: -1 | J33: 48.5 | K33: -0.5 | L33: 14.5 | M33: 1.5 | N33: =H33-J33 -> -12.5 | O33: -0.5 | R33: 39 | S33: 39 | T33: =R33-S33 -> 0 | AA33: For Con: Are you satisfied or dissatisfied with X as Y?
B34: Nov | C34: 22-26 | D34: 21146 | F34: Gallup | G34: News Chron | H34: 38.5 | I34: 2.5 | J34: 49 | K34: 0.5 | L34: 12 | M34: -2.5 | N34: =H34-J34 -> -10.5 | O34: 2
B35: Dec | F35: Gallup | G35: News Chron | H35: 41.5 | I35: 3 | J35: 47.5 | K35: -1.5 | L35: 9.5 | M35: -2.5 | N35: =H35-J35 -> -6 | O35: 4.5
A36: 1958 | B36: Jan | C36: 17-23 | D36: 21202 | F36: Gallup | G36: News Chron | H36: 40 | I36: -1.5 | J36: 47.5 | K36: 0 | L36: 12 | M36: 2.5 | N36: =H36-J36 -> -7.5 | O36: -1.5 | R36: 47 | S36: 37 | T36: =R36-S36 -> 10 | U36: 40 | V36: 23 | W36: =U36-V36 -> 17 | AA36: For Con: Are you satisified or dissatisfied with X as Y? For Lab: Do you think that X is or is not proving a good leader of Y? | AF36: 38 | AG36: 42 | AH36: =AF36-AG36 -> -4 | AI36: Do you approve or disapprove of the government's record to date?
B37: Feb | C37: 14-19 | D37: 21230 | F37: Gallup | G37: News Chron | H37: 36 | I37: -4 | J37: 44.5 | K37: -3 | L37: 18.5 | M37: 6.5 | N37: =H37-J37 -> -8.5 | O37: -1 | R37: 35 | S37: 41 | T37: =R37-S37 -> -6 | AA37: For Con: Are you satisfied or dissatisfied with X as Y?
B38: Mar | F38: Gallup | G38: News Chron | P38: Poll conducted but results lost by Gallup. Gallup 2 vols has answers for a non-standard VI question
B39: Apr | C39: 19-23 | D39: 21294 | F39: Gallup | G39: News Chron | H39: 38 | J39: 46.5 | L39: 15 | N39: =H39-J39 -> -8.5 | R39: 37
B40: May | C40: 3-7 | D40: 21308 | F40: Gallup | G40: News Chron | H40: 34 | I40: -4 | J40: 47 | K40: 0.5 | L40: 19 | M40: 4 | N40: =H40-J40 -> -13 | O40: -4.5 | R40: 37 | S40: 40 | T40: =R40-S40 -> -3 | AA40: For Con: Are you satisfied or dissatisfied with X as Y? | AF40: 30 | AG40: 43 | AH40: =AF40-AG40 -> -13 | AI40: Do you approve or disapprove of the government's record to date?
...

Sheet 59-64
A1: Year | B1: Month | C1: Fieldwork | E1: Published | F1: Polling | G1: Publisher | H1: Con | J1: Lab | L1: LD | N1: Con lead | Q1: Leader: | R1: Con good | S1: Con bad | T1: Con net | U1: Lab good | V1: Lab bad | W1: Lab net | X1: LD good | Y1: LD bad | Z1: LD net | AA1: Question | AB1: Con Best PM | AC1: Lab Best PM | AD1: LD Best PM | AE1: Question | AF1: Govt good | AG1: Govt bad | AH1: Govt net | AI1: Question
A2: 1959 | B2: Oct | C2: 10-12 | D2: 21833 | F2: Gallup | G2: News Chron | H2: 48 | J2: 46 | L2: 5 | N2: =H2-J2 -> 2 | P2: Note: during this Parliament at least Gallup would publish figures that are the average of two consecutive weeks of polling. It appears that each week listed separately below. See Sunday Times 8/3/1964 for article by David Butler
B3: Nov | F3: Gallup | G3: News Chron | H3: 48 | I3: 0 | J3: 44 | K3: -2 | L3: 7 | M3: 2 | N3: =H3-J3 -> 4 | O3: 2
B4: Dec | F4: Gallup | G4: News Chron | H4: 47.5 | I4: -0.5 | J4: 44 | K4: 0 | L4: 7.5 | M4: 0.5 | N4: =H4-J4 -> 3.5 | O4: -0.5
A5: 1960 | B5: Jan | C5: 1-6 | D5: 21916 | F5: Gallup | G5: News Chron | H5: 47 | I5: -0.5 | J5: 43.5 | K5: -0.5 | L5: 8.5 | M5: 1 | N5: =H5-J5 -> 3.5 | O5: 0
B6: Jan | C6: 9-20 | D6: 21924 | F6: Gallup | G6: News Chron | H6: 47 | I6: 0 | J6: 42.5 | K6: -1 | L6: 9.5 | M6: 1 | N6: =H6-J6 -> 4.5 | O6: 1
B7: Feb | C7: 5-24 | D7: 21951 | F7: Gallup | G7: News Chron | H7: 47 | I7: 0 | J7: 43.5 | K7: 1 | L7: 9 | M7: -0.5 | N7: =H7-J7 -> 3.5 | O7: -1
B8: Mar | C8: 11-26 | D8: 21986 | F8: Gallup | G8: News Chron | H8: 47 | I8: 0 | J8: 42 | K8: -1.5 | L8: 10 | M8: 1 | N8: =H8-J8 -> 5 | O8: 1.5 | R8: 64 | S8: 19 | T8: =R8-S8 -> 45 | U8: 43 | V8: 23 | W8: =U8-V8 -> 20 | AA8: For Con: Are you satisified or dissatisfied with X as Y? For Lab: Do you think X is or is not proving a good leader of Y?
B9: Apr | C9: 6-27 | D9: 22012 | F9: Gallup | G9: News Chron | H9: 45 | I9: -2 | J9: 42.5 | K9: 0.5 | L9: 11.5 | M9: 1.5 | N9: =H9-J9 -> 2.5 | O9: -2.5 | R9: 57 | S9: 27 | T9: =R9-S9 -> 30 | U9: 40 | V9: 36 | W9: =U9-V9 -> 4 | AA9: For Con: Are you satisified or dissatisfied with X as Y? For Lab: Do you think X is or is not proving a good leader of Y?
B10: May | C10: 1-29 | D10: 22037 | F10: Gallup | G10: News Chron | H10: 45.5 | I10: 0.5 | J10: 42.5 | K10: 0 | L10: 11 | M10: -0.5 | N10: =H10-J10 -> 3 | O10: 0.5 | R10: 79 | S10: 16 | T10: =R10-S10 -> 63 | AA10: For Con: Are you satisified or dissatisfied with X as Y? For Lab: Do you think X is or is not proving a good leader of Y?
B11: Jun | C11: 3-29 | D11: 22070 | F11: Gallup | G11: News Chron | H11: 45.5 | I11: 0 | J11: 43 | K11: 0.5 | L11: 10.5 | M11: -0.5 | N11: =H11-J11 -> 2.5 | O11: -0.5 | R11: 70 | S11: 22 | T11: =R11-S11 -> 48 | U11: 56 | V11: 25 | W11: =U11-V11 -> 31 | AA11: For Con: Are you satisified or dissatisfied with X as Y? For Lab: Do you think X is or is not proving a good leader of Y?
B12: Jul | C12: 1-27 | D12: 22098 | F12: Gallup | G12: News Chron | H12: 47 | I12: 1.5 | J12: 43 | K12: 0 | L12: 9 | M12: -1.5 | N12: =H12-J12 -> 4 | O12: 1.5 | R12: 69 | S12: 18 | T12: =R12-S12 -> 51 | U12: 43 | V12: 34 | W12: =U12-V12 -> 9 | AA12: For Con: Are you satisified or dissatisfied with X as Y? For Lab: Do you think X is or is not proving a good leader of Y?
B13: Jul | D13: 22112 | F13: NOP | H13: 44.8 | J13: 34.2 | L13: 10 | N13: =H13-J13 -> 10.6
B14: Aug | C14: 25-5 | D14: 22153 | F14: Gallup | G14: News Chron | H14: 47.5 | I14: 0.5 | J14: 42 | K14: -1 | L14: 10 | M14: 1 | N14: =H14-J14 -> 5.5 | O14: 1.5 | R14: 65 | S14: 22 | T14: =R14-S14 -> 43 | U14: 43 | V14: 33 | W14: =U14-V14 -> 10 | AA14: For Con: Are you satisified or dissatisfied with X as Y? For Lab: Do you think X is or is not proving a good leader of Y?
B15: Sep | C15: 8-4 | D15: 22167 | F15: Gallup | G15: News Chron | H15: 47.5 | I15: 0 | J15: 40.5 | K15: -1.5 | L15: 11 | M15: 1 | N15: =H15-J15 -> 7 | O15: 1.5 | AF15: 59 | AG15: 24 | AH15: =AF15-AG15 -> 35 | AI15: Do you approve or disapprove of the government's record to date?
B16: Oct | C16: 20-2 | D16: 22209 | F16: Gallup | G16: News Chron | H16: 50 | I16: 2.5 | J16: 37 | K16: -3.5 | L16: 12.5 | M16: 1.5 | N16: =H16-J16 -> 13 | O16: 6 | R16: 74 | S16: 16 | T16: =R16-S16 -> 58 | U16: 43 | V16: 33 | W16: =U16-V16 -> 10 | AA16: For Con: Are you satisified or dissatisfied with X as Y? For Lab: Do you think X is or is not proving a good leader of Y? | AF16: 59 | AG16: 23 | AH16: =AF16-AG16 -> 36 | AI16: Do you approve or disapprove of the government's record to date?
B17: Nov | C17: 3-29 | D17: 22223 | F17: Gallup | H17: 46 | I17: -4 | J17: 40.5 | K17: 3.5 | L17: 13.5 | M17: 1 | N17: =H17-J17 -> 5.5 | O17: -7.5 | R17: 72 | S17: 14 | T17: =R17-S17 -> 58 | U17: 48 | V17: 27 | W17: =U17-V17 -> 21 | AA17: For Con: Are you satisified or dissatisfied with X as Y? For Lab: Do you think X is or is not proving a good leader of Y? | AF17: 59 | AG17: 20 | AH17: =AF17-AG17 -> 39 | AI17: Do you approve or disapprove of the government's record to date?
B18: Dec | F18: Gallup | H18: 47.5 | I18: 1.5 | J18: 37.5 | K18: -3 | L18: 14 | M18: 0.5 | N18: =H18-J18 -> 10 | O18: 4.5 | R18: 69 | S18: 19 | T18: =R18-S18 -> 50 | U18: 44 | V18: 32 | W18: =U18-V18 -> 12 | AA18: For Con: Are you satisified or dissatisfied with X as Y? For Lab: Do you think X is or is not proving a good leader of Y? | AF18: 56 | AG18: 23 | AH18: =AF18-AG18 -> 33 | AI18: Do you approve or disapprove of the government's record to date?
A19: 1961 | B19: Jan | F19: Gallup | G19: DT | H19: 45 | I19: -2.5 | J19: 41.5 | K19: 4 | L19: 12.5 | M19: -1.5 | N19: =H19-J19 -> 3.5 | O19: -6.5 | R19: 65 | S19: 23 | T19: =R19-S19 -> 42 | U19: 45 | V19: 31 | W19: =U19-V19 -> 14 | AA19: For Con: Are you satisified or dissatisfied with X as Y? For Lab: Do you think X is or is not proving a good leader of Y? | AF19: 48 | AG19: 32 | AH19: =AF19-AG19 -> 16 | AI19: Do you approve or disapprove of the government's record to date?
B20: Feb | F20: Gallup | G20: DT | H20: 44 | I20: -1 | J20: 42 | K20: 0.5 | L20: 13 | M20: 0.5 | N20: =H20-J20 -> 2 | O20: -1.5 | R20: 64 | S20: 26 | T20: =R20-S20 -> 38 | U20: 45 | V20: 32 | W20: =U20-V20 -> 13 | AA20: For Con: Are you satisified or dissatisfied with X as Y? For Lab: Do you think X is or is not proving a good leader of Y? | AF20: 48 | AG20: 32 | AH20: =AF20-AG20 -> 16 | AI20: Do you approve or disapprove of the government's record to date?
B21: Mar | C21: ?-6 | D21: 22341 | F21: NOP | U21: 63.6 | V21: 29.1 | W21: =U21-V21 -> 34.5 | AA21: Are you satisfied or dissatisfied with X as Y?
B22: Mar | C22: 3-8 | D22: 22343 | F22: Gallup | G22: DT | H22: 42 | I22: -2 | J22: 42 | K22: 0 | L22: 15 | M22: 2 | N22: =H22-J22 -> 0 | O22: -2 | P22: Not in the usual Gallup sources but from the team who digitised Gallup poll records - https://x.com/_johnkenny/status/1613304350343938050
B23: Mar | F23: Gallup | G23: DT | H23: 44 | I23: 2 | J23: 40 | K23: -2 | L23: 15 | M23: 0 | N23: =H23-J23 -> 4 | O23: 4 | P23: The Telegraph, Monday, Mar. 27, 1961, reports two Gallup polls in the month, neither with these figures and not averaging to this either. But these are the figures from Gallup, Public Opinion Polls, Vol1 (which probably averages different polls from the same month) | R23: 63 | S23: 27 | T23: =R23-S23 -> 36 | U23: 45 | V23: 37 | W23: =U23-V23 -> 8 | AA23: For Con: Are you satisified or dissatisfied with X as Y? For Lab: Do you think X is or is not proving a good leader of Y? | AF23: 51 | AG23: 30 | AH23: =AF23-AG23 -> 21 | AI23: Do you approve or disapprove of the government's record to date?
B24: Apr | C24: 21-26 | D24: 22392 | F24: Gallup | G24: DT | H24: 43.5 | I24: -0.5 | J24: 40.5 | K24: 0.5 | L24: 15 | M24: 0 | N24: =H24-J24 -> 3 | O24: -1 | R24: 64 | S24: 23 | T24: =R24-S24 -> 41 | U24: 43 | V24: 34 | W24: =U24-V24 -> 9 | AA24: For Con: Are you satisified or dissatisfied with X as Y? For Lab: Do you think X is or is not proving a good leader of Y? | AF24: 50 | AG24: 30 | AH24: =AF24-AG24 -> 20 | AI24: Do you approve or disapprove of the government's record to date?
B25: Apr | C25: 28-9 | D25: 22399 | E25: 31 | F25: Gallup | G25: DT | H25: 44.5 | I25: 1 | J25: 40.5 | K25: 0 | L25: 14 | M25: -1 | N25: =H25-J25 -> 4 | O25: 1 | R25: 58 | S25: 28 | T25: =R25-S25 -> 30 | U25: 45 | V25: 31 | W25: =U25-V25 -> 14 | AA25: For Con: Are you satisified or dissatisfied with X as Y? For Lab: Do you think X is or is not proving a good leader of Y? | AF25: 49 | AG25: 33 | AH25: =AF25-AG25 -> 16 | AI25: Do you approve or disapprove of the government's record to date?
B26: Jun | C26: ?-23 | D26: 22449 | F26: NOP | U26: 45.9 | V26: 29.7 | W26: =U26-V26 -> 16.2 | AA26: Are you satisfied or dissatisfied with X as Y?
B27: Jun | C27: 30-7 | D27: 22462 | E27: 26 | F27: Gallup | G27: DT | H27: 43.5 | I27: -1 | J27: 40 | K27: -0.5 | L27: 15 | M27: 1 | N27: =H27-J27 -> 3.5 | O27: -0.5 | R27: 58 | S27: 29 | T27: =R27-S27 -> 29 | U27: 45 | V27: 33 | W27: =U27-V27 -> 12 | AA27: For Con: Are you satisified or dissatisfied with X as Y? For Lab: Do you think X is or is not proving a good leader of Y? | AF27: 52 | AG27: 29 | AH27: =AF27-AG27 -> 23 | AI27: Do you approve or disapprove of the government's record to date?
B28: Jul | C28: 29-5 | D28: 22491 | F28: Gallup | G28: DT | H28: 44 | I28: 0.5 | J28: 41.5 | K28: 1.5 | L28: 14 | M28: -1 | N28: =H28-J28 -> 2.5 | O28: -1 | R28: 54 | S28: 33 | T28: =R28-S28 -> 21 | U28: 51 | V28: 30 | W28: =U28-V28 -> 21 | AA28: For Con: Are you satisified or dissatisfied with X as Y? For Lab: Do you think X is or is not proving a good leader of Y? | AF28: 49 | AG28: 36 | AH28: =AF28-AG28 -> 13 | AI28: Do you approve or disapprove of the government's record to date?
B29: Aug | C29: 2-9 | D29: 22495 | F29: Gallup | G29: DT | H29: 38 | I29: -6 | J29: 43 | K29: 1.5 | L29: 17 | M29: 3 | N29: =H29-J29 -> -5 | O29: -7.5 | R29: 45 | S29: 42 | T29: =R29-S29 -> 3 | U29: 47 | V29: 28 | W29: =U29-V29 -> 19 | AA29: For Con: Are you satisified or dissatisfied with X as Y? For Lab: Do you think X is or is not proving a good leader of Y? | AF29: 38 | AG29: 44 | AH29: =AF29-AG29 -> -6 | AI29: Do you approve or disapprove of the government's record to date?
B30: Aug | C30: ?-18 | D30: 22505 | F30: NOP | U30: 44.8 | V30: 31.6 | W30: =U30-V30 -> 13.2 | AA30: Are you satisfied or dissatisfied with X as Y?
B31: Aug | C31: 30-4 | D31: 22523 | F31: Gallup | G31: DT | H31: 40 | I31: 2 | J31: 45.5 | K31: 2.5 | L31: 13.5 | M31: -3.5 | N31: =H31-J31 -> -5.5 | O31: -0.5 | R31: 43 | S31: 44 | T31: =R31-S31 -> -1 | U31: 46 | V31: 27 | W31: =U31-V31 -> 19 | AA31: For Con: Are you satisified or dissatisfied with X as Y? For Lab: Do you think X is or is not proving a good leader of Y? | AF31: 39 | AG31: 43 | AH31: =AF31-AG31 -> -4 | AI31: Do you approve or disapprove of the government's record to date?
B32: Sep | C32: 24-2 | D32: 22548 | F32: Gallup | G32: DT | H32: 42.5 | I32: 2.5 | J32: 45 | K32: -0.5 | L32: 12 | M32: -1.5 | N32: =H32-J32 -> -2.5 | O32: 3
B33: Oct | C33: 12-16 | D33: 22566 | F33: Gallup | G33: DT | H33: 43.5 | I33: 1 | J33: 43.5 | K33: -1.5 | L33: 12 | M33: 0 | N33: =H33-J33 -> 0 | O33: 2.5 | R33: 55 | S33: 33 | T33: =R33-S33 -> 22 | U33: 57 | V33: 26 | W33: =U33-V33 -> 31 | AA33: For Con: Are you satisified or dissatisfied with X as Y? For Lab: Do you think X is or is not proving a good leader of Y? | AF33: 47 | AG33: 36 | AH33: =AF33-AG33 -> 11 | AI33: Do you approve or disapprove of the government's record to date?
B34: Nov | C34: ?-6 | D34: 22586 | F34: NOP | H34: 40 | I34: =H34-H13 -> -4.8 | J34: 32.7 | K34: =J34-J13 -> -1.5 | L34: 17.3 | M34: =L34-L13 -> 7.3 | N34: =H34-J34 -> 7.3 | O34: =N34-N13 -> -3.3 | R34: 52.9 | S34: 34 | T34: =R34-S34 -> 18.9 | U34: 51.2 | V34: 28.1 | W34: =U34-V34 -> 23.1 | AA34: Are you satisfied or dissatisfied with X as Y?
B35: Nov | C35: 2-7 | D35: 22587 | F35: Gallup | G35: DT | H35: 41.5 | I35: -2 | J35: 43 | K35: -0.5 | L35: 14.5 | M35: 2.5 | N35: =H35-J35 -> -1.5 | O35: -1.5 | R35: 54 | S35: 34 | T35: =R35-S35 -> 20 | U35: 52 | V35: 30 | W35: =U35-V35 -> 22 | AA35: For Con: Are you satisified or dissatisfied with X as Y? For Lab: Do you think X is or is not proving a good leader of Y? | AF35: 43 | AG35: 38 | AH35: =AF35-AG35 -> 5 | AI35: Do you approve or disapprove of the government's record to date?
B36: Nov | C36: 9-14 | D36: 22594 | F36: Gallup | G36: DT | H36: 39 | I36: -2.5 | J36: 40 | K36: -3 | L36: 20 | M36: 5.5 | N36: =H36-J36 -> -1 | O36: 0.5
B37: Nov | C37: ?-27 | D37: 22606 | F37: NOP | H37: 34.1 | I37: =H37-H34 -> -5.9 | J37: 33.6 | K37: =J37-J34 -> 0.9 | L37: 19.9 | M37: =L37-L34 -> 2.6 | N37: =H37-J37 -> 0.5 | O37: =N37-N34 -> -6.8 | R37: 54.5 | S37: 32.9 | T37: =R37-S37 -> 21.6 | U37: 50.8 | V37: 30.8 | W37: =U37-V37 -> 20 | AA37: Are you satisfied or dissatisfied with X as Y?
B38: Nov | C38: 30-6 | D38: 22615 | F38: Gallup | G38: DT | H38: 38.5 | I38: -0.5 | J38: 43 | K38: 3 | L38: 17.5 | M38: -2.5 | N38: =H38-J38 -> -4.5 | O38: -3.5
B39: Dec | C39: ?-15 | D39: 22624 | F39: NOP | H39: 35.2 | I39: =H39-H37 -> 1.1 | J39: 32 | K39: =J39-J37 -> -1.6 | L39: 19.5 | M39: =L39-L37 -> -0.4 | N39: =H39-J39 -> 3.2 | O39: =N39-N37 -> 2.7 | R39: 50.1 | S39: 38.3 | T39: =R39-S39 -> 11.8 | U39: 47.6 | V39: 31 | W39: =U39-V39 -> 16.6 | AA39: Are you satisfied or dissatisfied with X as Y?
A40: 1962 | B40: Jan | C40: ?-8 | D40: 22648 | F40: NOP | H40: 35.4 | I40: =H40-H39 -> 0.2 | J40: 34 | K40: =J40-J39 -> 2 | L40: 19.8 | M40: =L40-L39 -> 0.3 | N40: =H40-J40 -> 1.4 | O40: =N40-N39 -> -1.8 | R40: 52.3 | S40: 35.2 | T40: =R40-S40 -> 17.1 | U40: 48.4 | V40: 30.2 | W40: =U40-V40 -> 18.2 | AA40: Are you satisfied or dissatisfied with X as Y?
...

Sheet 64-66
A1: Year | B1: Month | C1: Fieldwork | E1: Published | F1: Polling | G1: Publisher | H1: Con | J1: Lab | L1: LD | N1: Con lead | Q1: Leader: | R1: Con good | S1: Con bad | T1: Con net | U1: Lab good | V1: Lab bad | W1: Lab net | X1: LD good | Y1: LD bad | Z1: LD net | AA1: Question | AB1: Con Best PM | AC1: Lab Best PM | AD1: LD Best PM | AE1: Question | AF1: Govt good | AG1: Govt bad | AH1: Govt net | AI1: Question
A2: 1964 | B2: Oct | C2: 22-25 | D2: 23672 | F2: NOP | G2: DM | H2: 36.6 | J2: 50.7 | L2: 12 | N2: =H2-J2 -> -14.1 | U2: 60.1 | V2: 11.9 | W2: =U2-V2 -> 48.2 | AA2: Are you satisfied or dissatisfied with the way X has begun his job as Y?
B3: Nov | C3: 5-8 | D3: 23686 | F3: NOP | G3: DM | H3: 39 | I3: =H3-H2 -> 2.4 | J3: 50.3 | K3: =J3-J2 -> -0.4 | L3: 10.5 | M3: =L3-L2 -> -1.5 | N3: =H3-J3 -> -11.3 | U3: 64.2 | V3: 24.5 | W3: =U3-V3 -> 39.7 | AA3: Are you satisfied or dissatisfied with the way X has begun his job as Y? | AF3: 57.7 | AG3: 21.2 | AH3: =AF3-AG3 -> 36.5 | AI3: Are you satisfied or dissatisfied with the way they have approached the job of governing the country?
B4: Nov | F4: Gallup | G4: DT | H4: 38.5 | J4: 50 | L4: 11 | N4: =H4-J4 -> -11.5 | R4: 39 | S4: 47 | T4: =R4-S4 -> -8 | U4: 60 | V4: 26 | W4: =U4-V4 -> 34 | X4: 69 | Y4: 10 | Z4: =X4-Y4 -> 59 | AA4: For Con: Do you think X is or is not proving a good leader of Y? For Lab: Are you satisified or dissatisfied with X as Y? For Lib: Do you think that X is or is not doing a good job as leader of Y? | AF4: 49 | AG4: 21 | AH4: =AF4-AG4 -> 28 | AI4: Do you approve or disapprove of the government's record to date?
B5: Nov | C5: 19-22 | D5: 23700 | F5: NOP | G5: DM | H5: 37.9 | I5: =H5-H3 -> -1.1 | J5: 51.3 | K5: =J5-J3 -> 1 | L5: 10.4 | M5: =L5-L3 -> -0.1 | N5: =H5-J5 -> -13.4 | O5: =N5-N3 -> -2.1 | R5: 48.2 | S5: 45.4 | T5: =R5-S5 -> 2.8 | U5: 64.9 | V5: 25 | W5: =U5-V5 -> 39.9 | AA5: Are you satisfied or dissatisfied with the way X has begun his job as Y? (PM) Are you satistified or dissatisfied with A as B? | AF5: 56.8 | AG5: 27.7 | AH5: =AF5-AG5 -> 29.1 | AI5: Are you satisfied or dissatisfied with the way they have approached the job of governing the country?
B6: Dec | C6: 3-7 | D6: 23714 | F6: NOP | G6: DM | H6: 38.8 | I6: =H6-H5 -> 0.9 | J6: 48.7 | K6: =J6-J5 -> -2.6 | L6: 12.2 | M6: =L6-L5 -> 1.8 | N6: =H6-J6 -> -9.9 | O6: =N6-N5 -> 3.5 | R6: 46 | S6: 40.6 | T6: =R6-S6 -> 5.4 | U6: 63.7 | V6: 26.4 | W6: =U6-V6 -> 37.3 | AA6: Are you satisfied or dissatisfied with the way X has begun his job as Y? (PM) Are you satistified or dissatisfied with A as B? | AF6: 54.5 | AG6: 28.8 | AH6: =AF6-AG6 -> 25.7 | AI6: Are you satisfied or dissatisfied with the way they have approached the job of governing the country?
B7: Dec | F7: Gallup | G7: DT | H7: 40 | I7: 1.5 | J7: 50.5 | K7: 0.5 | L7: 9 | M7: -2 | N7: =H7-J7 -> -10.5 | O7: 1 | R7: 41 | S7: 39 | T7: =R7-S7 -> 2 | U7: 64 | V7: 26 | W7: =U7-V7 -> 38 | X7: 74 | Y7: 7 | Z7: =X7-Y7 -> 67 | AA7: For Con: Do you think X is or is not proving a good leader of Y? For Lab: Are you satisified or dissatisfied with X as Y? For Lib: Do you think that X is or is not doing a good job as leader of Y? | AF7: 48 | AG7: 30 | AH7: =AF7-AG7 -> 18 | AI7: Do you approve or disapprove of the government's record to date?
A8: 1965 | B8: Jan | F8: Gallup | G8: DT | H8: 42.5 | I8: 2.5 | J8: 46.5 | K8: -4 | L8: 10.5 | M8: 1.5 | N8: =H8-J8 -> -4 | O8: 6.5 | R8: 38 | S8: 42 | T8: =R8-S8 -> -4 | U8: 56 | V8: 26 | W8: =U8-V8 -> 30 | X8: 58 | Y8: 10 | Z8: =X8-Y8 -> 48 | AA8: For Con: Do you think X is or is not proving a good leader of Y? For Lab: Are you satisified or dissatisfied with X as Y? For Lib: Do you think that X is or is not doing a good job as leader of Y? | AF8: 39 | AG8: 35 | AH8: =AF8-AG8 -> 4 | AI8: Do you approve or disapprove of the government's record to date?
B9: Jan | C9: 7-11 | D9: 23749 | F9: NOP | G9: DM | H9: 40.2 | I9: =H9-H6 -> 1.4 | J9: 48.8 | K9: 1.4 | L9: 10.4 | M9: 1.4 | N9: =H9-J9 -> -8.6 | O9: 1.4 | R9: 44.8 | S9: 45.2 | T9: =R9-S9 -> -0.4 | U9: 65.8 | V9: 24.2 | W9: =U9-V9 -> 41.6 | AA9: Are you satisfied or dissatisfied with the way X has begun his job as Y? (PM) Are you satistified or dissatisfied with A as B? | AF9: 51.4 | AG9: 33.2 | AH9: =AF9-AG9 -> 18.2 | AI9: Are you satisfied or dissatisfied with the way they have approached the job of governing the country?
